<?xml version="1.0" ?>
<!-- =================================================================================== -->
<!-- |    This document was autogenerated by xacro from C:\Users\harry\AppData\Local\Temp\tmpgiko9k9q.xacro | -->
<!-- |    EDITING THIS FILE BY HAND IS NOT RECOMMENDED                                 | -->
<!-- =================================================================================== -->
<robot name="ArkBot">
  <material name="silver">
    <color rgba="0.700 0.700 0.700 1.000"/>
  </material>
  <transmission name="Revolute 1_tran">
    <type>transmission_interface/SimpleTransmission</type>
    <joint name="Revolute 1">
      <hardwareInterface>hardware_interface/EffortJointInterface</hardwareInterface>
    </joint>
    <actuator name="Revolute 1_actr">
      <hardwareInterface>hardware_interface/EffortJointInterface</hardwareInterface>
      <mechanicalReduction>1</mechanicalReduction>
    </actuator>
  </transmission>
  <transmission name="Revolute 2_tran">
    <type>transmission_interface/SimpleTransmission</type>
    <joint name="Revolute 2">
      <hardwareInterface>hardware_interface/EffortJointInterface</hardwareInterface>
    </joint>
    <actuator name="Revolute 2_actr">
      <hardwareInterface>hardware_interface/EffortJointInterface</hardwareInterface>
      <mechanicalReduction>1</mechanicalReduction>
    </actuator>
  </transmission>
  <transmission name="Revolute 3_tran">
    <type>transmission_interface/SimpleTransmission</type>
    <joint name="Revolute 3">
      <hardwareInterface>hardware_interface/EffortJointInterface</hardwareInterface>
    </joint>
    <actuator name="Revolute 3_actr">
      <hardwareInterface>hardware_interface/EffortJointInterface</hardwareInterface>
      <mechanicalReduction>1</mechanicalReduction>
    </actuator>
  </transmission>
  <transmission name="Revolute 4_tran">
    <type>transmission_interface/SimpleTransmission</type>
    <joint name="Revolute 4">
      <hardwareInterface>hardware_interface/EffortJointInterface</hardwareInterface>
    </joint>
    <actuator name="Revolute 4_actr">
      <hardwareInterface>hardware_interface/EffortJointInterface</hardwareInterface>
      <mechanicalReduction>1</mechanicalReduction>
    </actuator>
  </transmission>
  <transmission name="Revolute 5_tran">
    <type>transmission_interface/SimpleTransmission</type>
    <joint name="Revolute 5">
      <hardwareInterface>hardware_interface/EffortJointInterface</hardwareInterface>
    </joint>
    <actuator name="Revolute 5_actr">
      <hardwareInterface>hardware_interface/EffortJointInterface</hardwareInterface>
      <mechanicalReduction>1</mechanicalReduction>
    </actuator>
  </transmission>
  <transmission name="Revolute 6_tran">
    <type>transmission_interface/SimpleTransmission</type>
    <joint name="Revolute 6">
      <hardwareInterface>hardware_interface/EffortJointInterface</hardwareInterface>
    </joint>
    <actuator name="Revolute 6_actr">
      <hardwareInterface>hardware_interface/EffortJointInterface</hardwareInterface>
      <mechanicalReduction>1</mechanicalReduction>
    </actuator>
  </transmission>
  <transmission name="Slider 7_tran">
    <type>transmission_interface/SimpleTransmission</type>
    <joint name="Slider 7">
      <hardwareInterface>hardware_interface/EffortJointInterface</hardwareInterface>
    </joint>
    <actuator name="Slider 7_actr">
      <hardwareInterface>hardware_interface/EffortJointInterface</hardwareInterface>
      <mechanicalReduction>1</mechanicalReduction>
    </actuator>
  </transmission>
  <gazebo>
    <plugin filename="libgazebo_ros_control.so" name="control"/>
  </gazebo>
  <gazebo reference="base_link">
    <material>Gazebo/Silver</material>
    <mu1>0.2</mu1>
    <mu2>0.2</mu2>
    <self_collide>true</self_collide>
    <gravity>true</gravity>
  </gazebo>
  <gazebo reference="Link1">
    <material>Gazebo/Silver</material>
    <mu1>0.2</mu1>
    <mu2>0.2</mu2>
    <self_collide>true</self_collide>
  </gazebo>
  <gazebo reference="link2">
    <material>Gazebo/Silver</material>
    <mu1>0.2</mu1>
    <mu2>0.2</mu2>
    <self_collide>true</self_collide>
  </gazebo>
  <gazebo reference="link3">
    <material>Gazebo/Silver</material>
    <mu1>0.2</mu1>
    <mu2>0.2</mu2>
    <self_collide>true</self_collide>
  </gazebo>
  <gazebo reference="link4">
    <material>Gazebo/Silver</material>
    <mu1>0.2</mu1>
    <mu2>0.2</mu2>
    <self_collide>true</self_collide>
  </gazebo>
  <gazebo reference="link5">
    <material>Gazebo/Silver</material>
    <mu1>0.2</mu1>
    <mu2>0.2</mu2>
    <self_collide>true</self_collide>
  </gazebo>
  <gazebo reference="Hand">
    <material>Gazebo/Silver</material>
    <mu1>0.2</mu1>
    <mu2>0.2</mu2>
    <self_collide>true</self_collide>
  </gazebo>
  <gazebo reference="finger1">
    <material>Gazebo/Silver</material>
    <mu1>0.2</mu1>
    <mu2>0.2</mu2>
    <self_collide>true</self_collide>
  </gazebo>
  <gazebo reference="finger2">
    <material>Gazebo/Silver</material>
    <mu1>0.2</mu1>
    <mu2>0.2</mu2>
    <self_collide>true</self_collide>
  </gazebo>
  <link name="base_link">
    <inertial>
      <origin rpy="0 0 0" xyz="1.627798830346459e-05 0.038788043101890254 0.012657311430416793"/>
      <mass value="5.279041030398897"/>
      <inertia ixx="0.015337" ixy="-2e-06" ixz="2e-06" iyy="0.013839" iyz="-0.000795" izz="0.027582"/>
    </inertial>
    <visual>
      <origin rpy="0 0 0" xyz="0 0 0"/>
      <geometry>
        <mesh filename="/meshes/visual/base_link.stl" scale="0.001 0.001 0.001"/>
      </geometry>
      <material name="silver"/>
    </visual>
    <collision>
      <origin rpy="0 0 0" xyz="0 0 0"/>
      <geometry>
        <mesh filename="/meshes/collision/base_link.stl" scale="0.001 0.001 0.001"/>
      </geometry>
    </collision>
  </link>
  <link name="Link1">
    <inertial>
      <origin rpy="0 0 0" xyz="-8.789698917545885e-07 -0.00209324666321261 0.06034546164127977"/>
      <mass value="3.55259145758094"/>
      <inertia ixx="0.009583" ixy="-3e-06" ixz="-0.0" iyy="0.009852" iyz="9e-05" izz="0.004821"/>
    </inertial>
    <visual>
      <origin rpy="0 0 0" xyz="-0.0 -0.06 -0.046"/>
      <geometry>
        <mesh filename="/meshes/visual/Link1_v2_1.stl" scale="0.001 0.001 0.001"/>
      </geometry>
      <material name="silver"/>
    </visual>
    <collision>
      <origin rpy="0 0 0" xyz="-0.0 -0.06 -0.046"/>
      <geometry>
        <mesh filename="/meshes/collision/Link1_v2_1.stl" scale="0.001 0.001 0.001"/>
      </geometry>
    </collision>
  </link>
  <link name="link2">
    <inertial>
      <origin rpy="0 0 0" xyz="4.5648705801939816e-05 0.017680813699606 0.1474793511706172"/>
      <mass value="4.329966529786294"/>
      <inertia ixx="0.081251" ixy="1e-06" ixz="-2.1e-05" iyy="0.081811" iyz="0.005798" izz="0.005045"/>
    </inertial>
    <visual>
      <origin rpy="0 0 0" xyz="0.0 -0.06 -0.149"/>
      <geometry>
        <mesh filename="/meshes/visual/link2_v2_1.stl" scale="0.001 0.001 0.001"/>
      </geometry>
      <material name="silver"/>
    </visual>
    <collision>
      <origin rpy="0 0 0" xyz="0.0 -0.06 -0.149"/>
      <geometry>
        <mesh filename="/meshes/collision/link2_v2_1.stl" scale="0.001 0.001 0.001"/>
      </geometry>
    </collision>
  </link>
  <link name="link3">
    <inertial>
      <origin rpy="0 0 0" xyz="-1.847661592824805e-05 -0.02606315938822895 0.06299775440518512"/>
      <mass value="3.239056584746587"/>
      <inertia ixx="0.019677" ixy="-0.0" ixz="2e-06" iyy="0.020844" iyz="-0.000379" izz="0.002775"/>
    </inertial>
    <visual>
      <origin rpy="0 0 0" xyz="-9.9e-05 -0.061867 -0.440081"/>
      <geometry>
        <mesh filename="/meshes/visual/link3_v2_1.stl" scale="0.001 0.001 0.001"/>
      </geometry>
      <material name="silver"/>
    </visual>
    <collision>
      <origin rpy="0 0 0" xyz="-9.9e-05 -0.061867 -0.440081"/>
      <geometry>
        <mesh filename="/meshes/collision/link3_v2_1.stl" scale="0.001 0.001 0.001"/>
      </geometry>
    </collision>
  </link>
  <link name="link4">
    <inertial>
      <origin rpy="0 0 0" xyz="0.0005635271959570314 0.023726686595274354 0.04715061702801071"/>
      <mass value="1.7025158483719638"/>
      <inertia ixx="0.003779" ixy="-0.0" ixz="-1.8e-05" iyy="0.002331" iyz="-6e-06" izz="0.002101"/>
    </inertial>
    <visual>
      <origin rpy="0 0 0" xyz="-9.9e-05 -0.01489 -0.631389"/>
      <geometry>
        <mesh filename="/meshes/visual/link4_v2_1.stl" scale="0.001 0.001 0.001"/>
      </geometry>
      <material name="silver"/>
    </visual>
    <collision>
      <origin rpy="0 0 0" xyz="-9.9e-05 -0.01489 -0.631389"/>
      <geometry>
        <mesh filename="/meshes/collision/link4_v2_1.stl" scale="0.001 0.001 0.001"/>
      </geometry>
    </collision>
  </link>
  <link name="link5">
    <inertial>
      <origin rpy="0 0 0" xyz="7.240975234131843e-05 0.000377618306209547 0.02592927980852644"/>
      <mass value="0.6135827464240919"/>
      <inertia ixx="0.000353" ixy="1e-06" ixz="0.0" iyy="0.000334" iyz="1e-06" izz="0.000369"/>
    </inertial>
    <visual>
      <origin rpy="0 0 0" xyz="-9.9e-05 -0.03869 -0.727628"/>
      <geometry>
        <mesh filename="/meshes/visual/link5_v2_1.stl" scale="0.001 0.001 0.001"/>
      </geometry>
      <material name="silver"/>
    </visual>
    <collision>
      <origin rpy="0 0 0" xyz="-9.9e-05 -0.03869 -0.727628"/>
      <geometry>
        <mesh filename="/meshes/collision/link5_v2_1.stl" scale="0.001 0.001 0.001"/>
      </geometry>
    </collision>
  </link>
  <link name="Hand">
    <inertial>
      <origin rpy="0 0 0" xyz="-7.861406339096539e-05 0.02320812243170746 0.06508389882077914"/>
      <mass value="2.2197201602974554"/>
      <inertia ixx="0.008115" ixy="0.0" ixz="5e-06" iyy="0.004805" iyz="1e-06" izz="0.004534"/>
    </inertial>
    <visual>
      <origin rpy="0 0 0" xyz="-9.9e-05 -0.01559 -0.773389"/>
      <geometry>
        <mesh filename="/meshes/visual/Hand_v2_1.stl" scale="0.001 0.001 0.001"/>
      </geometry>
      <material name="silver"/>
    </visual>
    <collision>
      <origin rpy="0 0 0" xyz="-9.9e-05 -0.01559 -0.773389"/>
      <geometry>
        <mesh filename="/meshes/collision/Hand_v2_1.stl" scale="0.001 0.001 0.001"/>
      </geometry>
    </collision>
  </link>
  <link name="finger1">
    <inertial>
      <origin rpy="0 0 0" xyz="-0.004999628701543117 -0.015384046201054255 0.015310449682612193"/>
      <mass value="0.653538155273753"/>
      <inertia ixx="0.000528" ixy="0.0" ixz="-0.0" iyy="0.000746" iyz="8.4e-05" izz="0.000395"/>
    </inertial>
    <visual>
      <origin rpy="0 0 0" xyz="-0.005223 -0.11939 -0.901003"/>
      <geometry>
        <mesh filename="/meshes/visual/finger_v2_1.stl" scale="0.001 0.001 0.001"/>
      </geometry>
      <material name="silver"/>
    </visual>
    <collision>
      <origin rpy="0 0 0" xyz="-0.005223 -0.11939 -0.901003"/>
      <geometry>
        <mesh filename="/meshes/collision/finger_v2_1.stl" scale="0.001 0.001 0.001"/>
      </geometry>
    </collision>
  </link>
  <link name="finger2">
    <inertial>
      <origin rpy="0 0 0" xyz="-0.00499962868826751 0.015383111119019108 0.015310449682611749"/>
      <mass value="0.6535381552737535"/>
      <inertia ixx="0.000528" ixy="0.0" ixz="0.0" iyy="0.000746" iyz="-8.4e-05" izz="0.000395"/>
    </inertial>
    <visual>
      <origin rpy="0 0 0" xyz="-0.005223 0.04061 -0.901003"/>
      <geometry>
        <mesh filename="/meshes/visual/finger_v2__1__1.stl" scale="0.001 0.001 0.001"/>
      </geometry>
      <material name="silver"/>
    </visual>
    <collision>
      <origin rpy="0 0 0" xyz="-0.005223 0.04061 -0.901003"/>
      <geometry>
        <mesh filename="/meshes/collision/finger_v2__1__1.stl" scale="0.001 0.001 0.001"/>
      </geometry>
    </collision>
  </link>
  <joint name="Revolute 1" type="continuous">
    <origin rpy="0 0 0" xyz="0.0 0.06 0.046"/>
    <parent link="base_link"/>
    <child link="Link1"/>
    <axis xyz="0.0 0.0 -1.0"/>
  </joint>
  <joint name="Revolute 2" type="revolute">
    <origin rpy="0 0 0" xyz="-0.0 0.0 0.103"/>
    <parent link="Link1"/>
    <child link="link2"/>
    <axis xyz="-0.0 1.0 0.0"/>
    <limit effort="100" lower="-2.268928" upper="2.268928" velocity="100"/>
  </joint>
  <joint name="Revolute 3" type="revolute">
    <origin rpy="0 0 0" xyz="9.9e-05 0.001867 0.291081"/>
    <parent link="link2"/>
    <child link="link3"/>
    <axis xyz="-0.0 -1.0 -0.0"/>
    <limit effort="100" lower="-2.70526" upper="2.70526" velocity="100"/>
  </joint>
  <joint name="Revolute 4" type="revolute">
    <origin rpy="0 0 0" xyz="0.0 -0.046977 0.191308"/>
    <parent link="link3"/>
    <child link="link4"/>
    <axis xyz="-0.0 1.0 -0.0"/>
    <limit effort="100" lower="-2.356194" upper="2.356194" velocity="100"/>
  </joint>
  <joint name="Revolute 5" type="continuous">
    <origin rpy="0 0 0" xyz="0.0 0.0238 0.096239"/>
    <parent link="link4"/>
    <child link="link5"/>
    <axis xyz="0.0 -0.0 -1.0"/>
  </joint>
  <joint name="Revolute 6" type="revolute">
    <origin rpy="0 0 0" xyz="0.0 -0.0231 0.045761"/>
    <parent link="link5"/>
    <child link="Hand"/>
    <axis xyz="0.0 1.0 -0.0"/>
    <limit effort="100" lower="-2.356194" upper="2.356194" velocity="100"/>
  </joint>
  <joint name="Slider 7" type="prismatic">
    <origin rpy="0 0 0" xyz="0.005124 0.1038 0.127614"/>
    <parent link="Hand"/>
    <child link="finger1"/>
    <axis xyz="0.0 -1.0 0.0"/>
    <limit effort="100" lower="0.0" upper="0.0425" velocity="100"/>
  </joint>

<!-- Mirrored finger, driven by the same motor via mimic -->
<joint name="Slider 8" type="prismatic">
  <origin rpy="0 0 0" xyz="0.005124 -0.1038 0.127614"/>
  <parent link="Hand"/>
  <child link="finger2"/>
  <!-- Opposite axis to open/close symmetrically -->
  <axis xyz="0 1 0"/>
  <limit effort="100" lower="0.0" upper="0.0425" velocity="1.0"/>
  <mimic joint="Slider 7" multiplier="1.0" offset="0.0"/>
</joint>

</robot>